{
	"registryname": "alloy_transformer",
    "localizedname": "Alloy Transformer",
    "parts": [
        {
            "x": -1,
            "y": 0,
            "z": 0,
            
            "elements": [
                "tconstruct:seared@3"
            ]
        },
        {
            "x": 1,
            "y": 2,
            "z": 1,
           
            "elements": [
                "bigreactors:turbinerotorshaft@0"
            ]
        },
        {
            "x": 2,
            "y": 2,
            "z": 1,
            
            "elements": [
                "tconstruct:seared@3"
            ]
        },
        {
            "x": 1,
            "y": 0,
            "z": 0,
            
            "elements": [
                "tconstruct:seared@3"
            ]
        },
        {
            "x": -1,
            "y": 0,
            "z": 4,
            
            "elements": [
                "tconstruct:seared@3"
            ]
        },
        {
            "x": -1,
            "y": -2,
            "z": 3,
            
            "elements": [
                "tconstruct:seared@3"
            ]
        },
        {
            "x": 0,
            "y": 0,
            "z": 4,
           
            "elements": [
                "modularmachinery:blockenergyinputhatch"
            ]
        },
        {
            "x": 0,
            "y": -2,
            "z": 3,
            
            "elements": [
                "tconstruct:seared@3"
            ]
        },
        {
            "x": 1,
            "y": 0,
            "z": 4,
            
            "elements": [
                "tconstruct:seared@3"
            ]
        },
        {
            "x": 1,
            "y": -2,
            "z": 3,
            
            "elements": [
                "tconstruct:seared@3"
            ]
        },
        {
            "x": -2,
            "y": 3,
            "z": 1,
            
            "elements": [
                "tconstruct:seared@3"
            ]
        },
        {
            "x": -1,
            "y": 3,
            "z": 1,
            
            "elements": [
                "tconstruct:seared@3"
            ]
        },
        {
            "x": 1,
            "y": -1,
            "z": 0,
            
            "elements": [
                "tconstruct:seared@3"
            ]
        },
        {
            "x": 0,
            "y": -1,
            "z": 0,
            
            "elements": [
                "tconstruct:seared@3"
            ]
        },
        {
            "x": 0,
            "y": 3,
            "z": 1,
            
            "elements": [
                "tconstruct:seared@3"
            ]
        },
        {
            "x": -1,
            "y": 1,
            "z": 0,
            
            "elements": [
                "tconstruct:seared@3"
            ]
        },
        {
            "x": 1,
            "y": 3,
            "z": 1,
            
            "elements": [
                "tconstruct:seared@3"
            ]
        },
        {
            "x": 0,
            "y": 1,
            "z": 0,
            "elements": [
                "projectred-exploration:stone@7"
            ]
        },
        {
            "x": -1,
            "y": -1,
            "z": 0,
            
            "elements": [
                "tconstruct:seared@3"
            ]
        },
        {
            "x": 2,
            "y": 3,
            "z": 1,
            
            "elements": [
                "tconstruct:seared@3"
            ]
        },
        {
            "x": 1,
            "y": 1,
            "z": 0,
            
            "elements": [
                "tconstruct:seared@3"
            ]
        },
        {
            "x": -2,
            "y": -1,
            "z": 3,
            
            "elements": [
                "tconstruct:seared@3"
            ]
        },
        {
            "x": -1,
            "y": 1,
            "z": 4,
            
            "elements": [
                "tconstruct:seared@3"
            ]
        },
        {
            "x": 0,
            "y": 1,
            "z": 4,
            
            "elements": [
                "tconstruct:seared@3"
            ]
        },
        {
            "x": -1,
            "y": -1,
            "z": 3,
            "elements": [
                "projectred-exploration:stone@11"
            ]
        },
        {
            "x": 0,
            "y": -1,
            "z": 3,
            "elements": [
                "projectred-exploration:stone@11"
            ]
        },
        {
            "x": 1,
            "y": 1,
            "z": 4,
            
            "elements": [
                "tconstruct:seared@3"
            ]
        },
        {
            "x": 1,
            "y": -1,
            "z": 3,
            "elements": [
                "projectred-exploration:stone@11"
            ]
        },
        {
            "x": 2,
            "y": -1,
            "z": 3,
            
            "elements": [
                "tconstruct:seared@3"
            ]
        },
        {
            "x": -1,
            "y": 2,
            "z": 0,
            
            "elements": [
                "tconstruct:seared@3"
            ]
        },
        {
            "x": 0,
            "y": 2,
            "z": 0,
            
            "elements": [
                "tconstruct:seared@3"
            ]
        },
        {
            "x": 1,
            "y": 2,
            "z": 0,
            
            "elements": [
                "tconstruct:seared@3"
            ]
        },
        {
            "x": -2,
            "y": 0,
            "z": 3,
            
            "elements": [
                "tconstruct:seared@3"
            ]
        },
        {
            "x": -1,
            "y": 2,
            "z": 4,
            
            "elements": [
                "tconstruct:seared@3"
            ]
        },
        {
            "x": 0,
            "y": 2,
            "z": 4,
            
            "elements": [
                "tconstruct:seared@3"
            ]
        },
        {
            "x": -1,
            "y": 0,
            "z": 3,
            
            "elements": [
                "bigreactors:turbinerotorshaft@0"
            ]
        },
        {
            "x": -1,
            "y": -2,
            "z": 2,
            
            "elements": [
                "tconstruct:seared@3"
            ]
        },
        {
            "x": 0,
            "y": 0,
            "z": 3,
            "elements": [
                "nuclearcraft:cooler@0"
            ]
        },
        {
            "x": 1,
            "y": 2,
            "z": 4,
            
            "elements": [
                "tconstruct:seared@3"
            ]
        },
        {
            "x": 0,
            "y": -2,
            "z": 2,
            
            "elements": [
                "tconstruct:seared@3"
            ]
        },
        {
            "x": 1,
            "y": 0,
            "z": 3,
            
            "elements": [
                "bigreactors:turbinerotorshaft@0"
            ]
        },
        {
            "x": 2,
            "y": 0,
            "z": 3,
            
            "elements": [
                "modularmachinery:blockfluidinputhatch"
            ]
        },
        {
            "x": 1,
            "y": -2,
            "z": 2,
            
            "elements": [
                "tconstruct:seared@3"
            ]
        },
        {
            "x": -1,
            "y": 3,
            "z": 0,
            
            "elements": [
                "tconstruct:seared@3"
            ]
        },
        {
            "x": 0,
            "y": 3,
            "z": 0,
            
            "elements": [
                "tconstruct:seared@3"
            ]
        },
        {
            "x": 1,
            "y": 3,
            "z": 0,
            
            "elements": [
                "tconstruct:seared@3"
            ]
        },
        {
            "x": -2,
            "y": 1,
            "z": 3,
            
            "elements": [
                "tconstruct:seared@3"
            ]
        },
        {
            "x": -1,
            "y": 3,
            "z": 4,
            
            "elements": [
                "tconstruct:seared@3"
            ]
        },
        {
            "x": 0,
            "y": 3,
            "z": 4,
            
            "elements": [
                "tconstruct:seared@3"
            ]
        },
        {
            "x": -2,
            "y": -1,
            "z": 2,
            
            "elements": [
                "tconstruct:seared@3"
            ]
        },
        {
            "x": -1,
            "y": 1,
            "z": 3,
           
            "elements": [
                "bigreactors:turbinerotorshaft@0"
            ]
        },
        {
            "x": 1,
            "y": 3,
            "z": 4,
            
            "elements": [
                "tconstruct:seared@3"
            ]
        },
        {
            "x": 0,
            "y": 1,
            "z": 3,
            "elements": [
                "nuclearcraft:cooler@0"
            ]
        },
        {
            "x": -1,
            "y": -1,
            "z": 2,
            "elements": [
                "projectred-exploration:stone@11"
            ]
        },
        {
            "x": 0,
            "y": -1,
            "z": 2,
            "elements": [
                "minecraft:glass@0"
            ]
        },
        {
            "x": 1,
            "y": 1,
            "z": 3,
           
            "elements": [
                "bigreactors:turbinerotorshaft@0"
            ]
        },
        {
            "x": 2,
            "y": 1,
            "z": 3,
            
            "elements": [
                "modularmachinery:blockfluidinputhatch"
            ]
        },
        {
            "x": 1,
            "y": -1,
            "z": 2,
            "elements": [
                "projectred-exploration:stone@11"
            ]
        },
        {
            "x": 2,
            "y": -1,
            "z": 2,
            
            "elements": [
                "tconstruct:seared@3"
            ]
        },
        {
            "x": -2,
            "y": 2,
            "z": 3,
            
            "elements": [
                "tconstruct:seared@3"
            ]
        },
        {
            "x": -2,
            "y": 0,
            "z": 2,
            
            "elements": [
                "modularmachinery:blockfluidoutputhatch"
            ]
        },
        {
            "x": -1,
            "y": 2,
            "z": 3,
           
            "elements": [
                "bigreactors:turbinerotorshaft@0"
            ]
        },
        {
            "x": 0,
            "y": 2,
            "z": 3,
            "elements": [
                "nuclearcraft:cooler@0"
            ]
        },
        {
            "x": -1,
            "y": 0,
            "z": 2,
            "elements": [
                "nuclearcraft:cooler@0"
            ]
        },
        {
            "x": 0,
            "y": 0,
            "z": 2,
            "elements": [
                "minecraft:glass@0"
            ]
        },
        {
            "x": 1,
            "y": 2,
            "z": 3,
           
            "elements": [
                "bigreactors:turbinerotorshaft@0"
            ]
        },
        {
            "x": -1,
            "y": -2,
            "z": 1,
            
            "elements": [
                "tconstruct:seared@3"
            ]
        },
        {
            "x": 0,
            "y": -2,
            "z": 1,
            
            "elements": [
                "tconstruct:seared@3"
            ]
        },
        {
            "x": 2,
            "y": 2,
            "z": 3,
            
            "elements": [
                "tconstruct:seared@3"
            ]
        },
        {
            "x": 1,
            "y": 0,
            "z": 2,
            "elements": [
                "nuclearcraft:cooler@0"
            ]
        },
        {
            "x": 2,
            "y": 0,
            "z": 2,
            
            "elements": [
                "modularmachinery:blockfluidinputhatch"
            ]
        },
        {
            "x": 1,
            "y": -2,
            "z": 1,
            
            "elements": [
                "tconstruct:seared@3"
            ]
        },
        {
            "x": -2,
            "y": 3,
            "z": 3,
            
            "elements": [
                "tconstruct:seared@3"
            ]
        },
        {
            "x": -2,
            "y": 1,
            "z": 2,
            "elements": [
                "projectred-exploration:stone@5"
            ]
        },
        {
            "x": -1,
            "y": 3,
            "z": 3,
            
            "elements": [
                "tconstruct:seared@3"
            ]
        },
        {
            "x": 0,
            "y": 3,
            "z": 3,
            
            "elements": [
                "tconstruct:seared@3"
            ]
        },
        {
            "x": -2,
            "y": -1,
            "z": 1,
            
            "elements": [
                "tconstruct:seared@3"
            ]
        },
        {
            "x": -1,
            "y": 1,
            "z": 2,
            "elements": [
                "nuclearcraft:cooler@0"
            ]
        },
        {
            "x": 1,
            "y": 3,
            "z": 3,
            
            "elements": [
                "tconstruct:seared@3"
            ]
        },
        {
            "x": 0,
            "y": 1,
            "z": 2,
            "elements": [
                "minecraft:glass@0"
            ]
        },
        {
            "x": -1,
            "y": -1,
            "z": 1,
            "elements": [
                "projectred-exploration:stone@11"
            ]
        },
        {
            "x": 0,
            "y": -1,
            "z": 1,
            "elements": [
                "projectred-exploration:stone@11"
            ]
        },
        {
            "x": 2,
            "y": 3,
            "z": 3,
            
            "elements": [
                "tconstruct:seared@3"
            ]
        },
        {
            "x": 1,
            "y": 1,
            "z": 2,
            "elements": [
                "nuclearcraft:cooler@0"
            ]
        },
        {
            "x": 2,
            "y": 1,
            "z": 2,
            "elements": [
                "projectred-exploration:stone@6"
            ]
        },
        {
            "x": 1,
            "y": -1,
            "z": 1,
            "elements": [
                "projectred-exploration:stone@11"
            ]
        },
        {
            "x": 2,
            "y": -1,
            "z": 1,
            
            "elements": [
                "tconstruct:seared@3"
            ]
        },
        {
            "x": -2,
            "y": 2,
            "z": 2,
            
            "elements": [
                "tconstruct:seared@3"
            ]
        },
        {
            "x": -2,
            "y": 0,
            "z": 1,
            
            "elements": [
                "tconstruct:seared@3"
            ]
        },
        {
            "x": -1,
            "y": 2,
            "z": 2,
            "elements": [
                "nuclearcraft:cooler@0"
            ]
        },
        {
            "x": 0,
            "y": 2,
            "z": 2,
            "elements": [
                "minecraft:glass@0"
            ]
        },
        {
            "x": -1,
            "y": 0,
            "z": 1,
            
            "elements": [
                "bigreactors:turbinerotorshaft@0"
            ]
        },
        {
            "x": 0,
            "y": 0,
            "z": 1,
            "elements": [
                "nuclearcraft:cooler@0"
            ]
        },
        {
            "x": 1,
            "y": 2,
            "z": 2,
            "elements": [
                "nuclearcraft:cooler@0"
            ]
        },
        {
            "x": 2,
            "y": 2,
            "z": 2,
            
            "elements": [
                "tconstruct:seared@3"
            ]
        },
        {
            "x": 1,
            "y": 0,
            "z": 1,
            
            "elements": [
                "bigreactors:turbinerotorshaft@0"
            ]
        },
        {
            "x": 2,
            "y": 0,
            "z": 1,
            
            "elements": [
                "modularmachinery:blockfluidinputhatch"
            ]
        },
        {
            "x": -2,
            "y": 3,
            "z": 2,
            
            "elements": [
                "tconstruct:seared@3"
            ]
        },
        {
            "x": -2,
            "y": 1,
            "z": 1,
            
            "elements": [
                "tconstruct:seared@3"
            ]
        },
        {
            "x": -1,
            "y": 3,
            "z": 2,
            
            "elements": [
                "tconstruct:seared@3"
            ]
        },
        {
            "x": 0,
            "y": 3,
            "z": 2,
            "elements": [
                "minecraft:glass@0"
            ]
        },
        {
            "x": -1,
            "y": 1,
            "z": 1,
           
            "elements": [
                "bigreactors:turbinerotorshaft@0"
            ]
        },
        {
            "x": 1,
            "y": 3,
            "z": 2,
            
            "elements": [
                "tconstruct:seared@3"
            ]
        },
        {
            "x": 0,
            "y": 1,
            "z": 1,
            "elements": [
                "nuclearcraft:cooler@0"
            ]
        },
        {
            "x": 2,
            "y": 3,
            "z": 2,
            
            "elements": [
                "tconstruct:seared@3"
            ]
        },
        {
            "x": 1,
            "y": 1,
            "z": 1,
           
            "elements": [
                "bigreactors:turbinerotorshaft@0"
            ]
        },
        {
            "x": 2,
            "y": 1,
            "z": 1,
            
            "elements": [
                "modularmachinery:blockfluidinputhatch"
            ]
        },
        {
            "x": -1,
            "y": -1,
            "z": 4,
            
            "elements": [
                "tconstruct:seared@3"
            ]
        },
        {
            "x": 0,
            "y": -1,
            "z": 4,
            
            "elements": [
                "tconstruct:seared@3"
            ]
        },
        {
            "x": 1,
            "y": -1,
            "z": 4,
            
            "elements": [
                "tconstruct:seared@3"
            ]
        },
        {
            "x": -2,
            "y": 2,
            "z": 1,
            
            "elements": [
                "tconstruct:seared@3"
            ]
        },
        {
            "x": -1,
            "y": 2,
            "z": 1,
           
            "elements": [
                "bigreactors:turbinerotorshaft@0"
            ]
        },
        {
            "x": 0,
            "y": 2,
            "z": 1,
            "elements": [
                "nuclearcraft:cooler@0"
            ]
        }
    ]}